Workbook

Sheet Fig1 Global & Regional Stacks
A1: All stacks relative to 1870-1889 HadSST1.1 and reported in ΔT (°C) | C1: Age (ka) | D1: Global -2sd | E1: Global Mean | F1: Global +2sd | G1: Tropics -2sd | H1: Tropical Mean | I1: Tropical +2sd | J1: NH Extratropics -2sd | K1: NH Extratropics Mean | L1: NH Extratropics +2sd | M1: SH Extratropics -2sd | N1: SH Extratropics Mean | O1: SH Extratropics +2sd | P1: NATL Extratropics -2sd | Q1: NATL Extratropics Mean | R1: NATL Extratropics +2sd | S1: SATL Extratropics -2sd | T1: SATL Extratropics Mean | U1: SATL Extratropics +2sd | W1: Global stack relative to 1995-2014 HadSST1.1 | X1: Age (ka) | Y1: Global_1995 -2sd | Z1: Global_1995 Mean | AA1: Global_1995 +2sd
C2: 115 | D2: -1.1577988 | E2: -0.84802192 | F2: -0.53824508 | G2: -1.5830913 | H2: -1.1845608 | I2: -0.78603035 | J2: -1.2589478 | K2: -0.65454322 | L2: -0.050138533 | M2: -0.91484398 | N2: -0.2308197 | O2: 0.45320457 | P2: -1.761078 | Q2: -1.0160294 | R2: -0.27098072 | S2: 0.04514724 | T2: 0.88236415 | U2: 1.7195811 | X2: 115 | Y2: -1.5609601 | Z2: -1.2574457 | AA2: -0.95393139
C3: 115.1 | D3: -1.1406133 | E3: -0.83241236 | F3: -0.52421141 | G3: -1.576439 | H3: -1.1781144 | I3: -0.77978981 | J3: -1.2351238 | K3: -0.62900627 | L3: -0.02288878 | M3: -0.89397776 | N3: -0.21000263 | O3: 0.47397253 | P3: -1.7306435 | Q3: -0.98207742 | R3: -0.23351139 | S3: 0.056158841 | T3: 0.90096706 | U3: 1.7457752 | X3: 115.1 | Y3: -1.5444286 | Z3: -1.2413473 | AA3: -0.93826604
C4: 115.2 | D4: -1.1261675 | E4: -0.81629658 | F4: -0.50642562 | G4: -1.5719912 | H4: -1.1710829 | I4: -0.77017444 | J4: -1.2098639 | K4: -0.60330701 | L4: 0.003249884 | M4: -0.8731581 | N4: -0.1885294 | O4: 0.49609926 | P4: -1.6931052 | Q4: -0.94758093 | R4: -0.20205671 | S4: 0.072519064 | T4: 0.92055833 | U4: 1.7685976 | X4: 115.2 | Y4: -1.5290515 | Z4: -1.2243589 | AA4: -0.91966629
C5: 115.3 | D5: -1.1130729 | E5: -0.7996555 | F5: -0.48623815 | G5: -1.5711894 | H5: -1.1635758 | I5: -0.75596213 | J5: -1.1876345 | K5: -0.57800305 | L5: 0.031628311 | M5: -0.84749466 | N5: -0.16549273 | O5: 0.51650923 | P5: -1.658955 | Q5: -0.9144035 | R5: -0.16985202 | S5: 0.095971763 | T5: 0.94056892 | U5: 1.785166 | X5: 115.3 | Y5: -1.5146949 | Z5: -1.2070454 | AA5: -0.89939594
C6: 115.4 | D6: -1.0979462 | E6: -0.78354722 | F6: -0.46914834 | G6: -1.565871 | H6: -1.1565721 | I6: -0.74727321 | J6: -1.1665502 | K6: -0.55335021 | L6: 0.059849739 | M6: -0.82399315 | N6: -0.14272642 | O6: 0.5385403 | P6: -1.626713 | Q6: -0.88214594 | R6: -0.1375789 | S6: 0.11643749 | T6: 0.96079189 | U6: 1.8051462 | X6: 115.4 | Y6: -1.5011716 | Z6: -1.1918396 | AA6: -0.88250756
C7: 115.5 | D7: -1.0826113 | E7: -0.76884663 | F7: -0.455082 | G7: -1.5612082 | H7: -1.1509066 | I7: -0.74060488 | J7: -1.141813 | K7: -0.52906573 | L7: 0.083681524 | M7: -0.80063587 | N7: -0.12339109 | O7: 0.55385369 | P7: -1.5890203 | Q7: -0.84775102 | R7: -0.10648173 | S7: 0.13173139 | T7: 0.97893411 | U7: 1.8261368 | X7: 115.5 | Y7: -1.488449 | Z7: -1.1767887 | AA7: -0.8651284
C8: 115.6 | D8: -1.0696535 | E8: -0.75477576 | F8: -0.43989798 | G8: -1.5586059 | H8: -1.1461812 | I8: -0.73375654 | J8: -1.118169 | K8: -0.5048722 | L8: 0.10842454 | M8: -0.78182417 | N8: -0.10373928 | O8: 0.57434565 | P8: -1.5563525 | Q8: -0.81434548 | R8: -0.072338462 | S8: 0.15029508 | T8: 0.99958742 | U8: 1.8488798 | X8: 115.6 | Y8: -1.4743338 | Z8: -1.1616882 | AA8: -0.84904271
C9: 115.7 | D9: -1.0548398 | E9: -0.73920882 | F9: -0.42357773 | G9: -1.5548315 | H9: -1.1395872 | I9: -0.72434288 | J9: -1.0925938 | K9: -0.48066682 | L9: 0.13126016 | M9: -0.76392591 | N9: -0.081733868 | O9: 0.60045815 | P9: -1.5199393 | Q9: -0.7826134 | R9: -0.04528749 | S9: 0.16490549 | T9: 1.0196605 | U9: 1.8744154 | X9: 115.7 | Y9: -1.457711 | Z9: -1.1455519 | AA9: -0.83339286
C10: 115.8 | D10: -1.0409136 | E10: -0.72254014 | F10: -0.40416667 | G10: -1.5511266 | H10: -1.1312746 | I10: -0.71142256 | J10: -1.0695347 | K10: -0.45610446 | L10: 0.15732574 | M10: -0.74533635 | N10: -0.059503529 | O10: 0.62632924 | P10: -1.4826636 | Q10: -0.75159252 | R10: -0.020521402 | S10: 0.17332011 | T10: 1.0365535 | U10: 1.8997869 | X10: 115.8 | Y10: -1.4425201 | Z10: -1.1284851 | AA10: -0.81445003
C11: 115.9 | D11: -1.0240495 | E11: -0.70565224 | F11: -0.38725495 | G11: -1.5419117 | H11: -1.1233776 | I11: -0.7048434 | J11: -1.0442567 | K11: -0.43006277 | L11: 0.18413115 | M11: -0.72212678 | N11: -0.038016282 | O11: 0.64609426 | P11: -1.4483606 | Q11: -0.71859968 | R11: 0.011161208 | S11: 0.1835959 | T11: 1.0533189 | U11: 1.9230418 | X11: 115.9 | Y11: -1.4262843 | Z11: -1.1114211 | AA11: -0.7965579
C12: 116 | D12: -1.005255 | E12: -0.68804532 | F12: -0.37083569 | G12: -1.5281316 | H12: -1.1145846 | I12: -0.70103753 | J12: -1.0165415 | K12: -0.40412596 | L12: 0.20828953 | M12: -0.69815916 | N12: -0.01421581 | O12: 0.6697275 | P12: -1.4124491 | Q12: -0.68600839 | R12: 0.040432394 | S12: 0.19944328 | T12: 1.0705984 | U12: 1.9417534 | X12: 116 | Y12: -1.4080014 | Z12: -1.0947204 | AA12: -0.78143936
C13: 116.1 | D13: -0.98848045 | E13: -0.67113096 | F13: -0.35378146 | G13: -1.5215298 | H13: -1.1070101 | I13: -0.69249046 | J13: -0.98701274 | K13: -0.37781367 | L13: 0.23138538 | M13: -0.67655069 | N13: 0.008984371 | O13: 0.69451946 | P13: -1.3749933 | Q13: -0.6541416 | R13: 0.066710114 | S13: 0.2188592 | T13: 1.089004 | U13: 1.9591489 | X13: 116.1 | Y13: -1.391965 | Z13: -1.0784951 | AA13: -0.76502526
... C152: 130 | D152: -0.46286595 | E152: -0.15535879 | F152: 0.15214837 | G152: -0.76199168 | H152: -0.33796027 | I152: 0.086071134 | J152: -1.332245 | K152: -0.69368517 | L152: -0.055125356 | M152: 0.32734203 | N152: 0.96311277 | O152: 1.5988835 | P152: -2.7589309 | Q152: -1.9208795 | R152: -1.082828 | S152: 0.88589579 | T152: 1.8764759 | U152: 2.8670561 | X152: 130 | Y152: -0.87688088 | Z152: -0.56832999 | AA152: -0.2597791

Sheet Reference Cores Tie Points
B2: Basin Reference Core | C2: Alignment Target | D2: Basin | E2: Depth (cm) | F2: Age (Speleo-Age, ka) | G2: Speleo Uncertainty (ka) | H2: Comments
B3: MD01-2444 | C3: Greenland Synthetic | D3: NATL | E3: 1918 | F3: 106.04 | G3: 1.2 | H3: Abrupt change in Grn_syn & SST
B4: Hodell et al., 2013 | E4: 1951 | F4: 109.67 | G4: 1.6 | H4: Abrupt change in Grn_syn & SST
E5: 1970 | F5: 111.36 | G5: 1.6 | H5: Abrupt change in Grn_syn & SST
E6: 2144 | F6: 129.71 | G6: 1.4 | H6: Abrupt rate change in Grn_syn & SST
E7: 2201 | F7: 135.98 | G7: 1.3 | H7: Start of Grn_syn increase
B9: MD02-2488 | C9: EDC δD | D9: IND | E9: 2347.0614 | F9: 106.20655 | G9: 1.2 | H9: Antarctic Isotope Maxima 24/23 transition
B10: Govin et al., 2009; 2012 | E10: 2430.9063 | F10: 111.26974 | G10: 1.6 | H10: Antarctic Isotope Maxima 25/24 transition
E11: 2470.5096 | F11: 114.43693 | G11: 1.6 | H11: Antarctic Isotope Maxima 25 start
E12: 2522.7753 | F12: 125.38205 | G12: 1.5 | H12: End temperature maxima
E13: 2549.022 | F13: 129.28102 | G13: 1.4 | H13: Temperature maxima
E14: 2554.7289 | F14: 131.41225 | G14: 1.4 | H14: Increased rate of temperature change | I14: *needed to bring temp in line with ice core & not create substantial lags in the benthic d18O record. See usage and definition also in Govin et al. (2012)
E15: 2571.7074 | F15: 133.05246 | G15: 1.4 | H15: Increased rate of temperature change
E16: 2659.2953 | F16: 136.93019 | G16: 1.6 | H16: Start of EDC & SST temperature increase
B18: MD97-2120 | C18: EDC δD | D18: PAC | E18: 1401.1016 | F18: 106.19001 | G18: 1.2 | H18: Antarctic Isotope Maxima 24/23 transition
B19: Pahnke et al., 2006 | E19: 1461.1821 | F19: 111.2482 | G19: 1.6 | H19: Antarctic Isotope Maxima 25/24 transition
E20: 1501.1195 | F20: 114.51708 | G20: 1.6 | H20: Antarctic Isotope Maxima 25 start
E21: 1541.5527 | F21: 125.38205 | G21: 1.4 | H21: End of post-temperature maxima oscillation & start of end-LIG decline
E22: 1591.017 | F22: 129.34 | G22: 1.5 | H22: Temperature maxima
E23: 1700.7636 | F23: 139.07771 | G23: 1.5 | H23: Penultimate glacial temperature minima
B25: ODP1089 | C25: EDC δD | D25: SATL | E25: 1800.1001 | F25: 106.20655 | G25: 1.2 | H25: Antarctic Isotope Maxima 24/23 transition
E26: 1839.9952 | F26: 111.26974 | G26: 1.6 | H26: Antarctic Isotope Maxima 25/24 transition
E27: 1890.1922 | F27: 119.21489 | G27: 1.6 | H27: End of LIG temperature plateau & increased rate of change
E28: 2010.0999 | F28: 129.29303 | G28: 1.5 | H28: Temperature maxima
E29: 2109.0872 | F29: 136.01588 | G29: 1.4 | H29: Penultimate deglacial temperature rate change
E30: 2229.0874 | F30: 139.15955 | G30: 1.5 | H30: Penultimate glacial temperature minima

Sheet HadSST & SynTrACE Bias Estimate
A1: Site | B1: Latitude | C1: Longitude | D1: Feb/Aug Site Bias HadSST (°C) | E1: Feb/Aug Site Bias HadSST ± | F1: Feb/Aug Site Bias TrACE (K) | G1: Feb/Aug Site Bias TrACE ±
A2: 'v2814_tf' | B2: 65 | C2: -30 | D2: 0.63546515 | E2: 0.19461474 | F2: 0.0132808 | G2: 0.079885699
A3: 'v2720_tf' | B3: 54 | C3: -46 | D3: 0.60381848 | E3: 0.22203267 | F3: 0.15234999 | G3: 0.091467701
A4: 'm234149_tf' | B4: 54 | C4: -20 | D4: 0.56952399 | E4: 0.14605607 | F4: 0.108365 | G4: 0.039536301
A5: 'v2382_tf' | B5: 53 | C5: -22 | D5: 0.55631757 | E5: 0.17057271 | F5: 0.072000302 | G5: 0.0392555
A6: 'k7081_tf' | B6: 50 | C6: -24 | D6: 0.62224519 | E6: 0.23647614 | F6: -0.020868801 | G6: 0.040800899
A7: 'v29179_tf' | B7: 44 | C7: -24 | D7: 0.6939376 | E7: 0.19538131 | F7: -0.1088 | G7: 0.0495563
A8: 'y72111_rad' | B8: 43 | C8: -126 | D8: 0.23601079 | E8: 0.25513309 | F8: 0.434926 | G8: 0.051070299
A9: 'd117_tf' | B9: 42 | C9: -53 | D9: 0.87663424 | E9: 0.3063581 | F9: -0.13199501 | G9: 0.087455101
A10: 'v3097_tf' | B10: 41 | C10: -33 | D10: 0.81101125 | E10: 0.18783411 | F10: -0.201649 | G10: 0.067827404
A11: 'gik15637_tf' | B11: 27 | C11: -19 | D11: -0.18408307 | E11: 0.14135695 | F11: -0.14437801 | G11: 0.054028802
A12: 'm123921_tf' | B12: 25 | C12: -17 | D12: -0.13291985 | E12: 0.18074976 | F12: -0.160845 | G12: 0.054549199
A13: 'tr12629_tf' | B13: 21 | C13: -94 | D13: -0.13121514 | E13: 0.17372219 | F13: -0.00206493 | G13: 0.037282601
... A45: 'md73025_rad' | B45: -44 | C45: 51 | D45: 0.58382082 | E45: 0.24856928 | F45: 0.114524 | G45: 0.0273109

Sheet TEMPLATE
A1: ID | B1: Longitude | C1: Latitude | D1: Proxy | E1: Tie Point Depth (cm) | F1: Tie Point Age (yr) | G1: Tie Point Uncertainty (yr) | H1: Hadley Bias Correction | I1: Hadley uncertainty | J1: TF Uncertainty | K1: SS Uncertainty | L1: Benthic d18O Depth (cm) | M1: Benthic d18O (per mil) | N1: Depth (cm) | O1: Proxy Value | P1: SST (ºC) | Q1: Biascorr | R1: Age (yr) | S1: SST -2sd | T1: SST mean | U1: SST +2sd
H2: Note: these data are absent in most sheets | N2: Note: because we have 1 sheet per proxy, these data are inferred from the same proxy.

Sheet NATL Data Read Me
A1: All NATL (North Atlantic Ocean) site metadata, including the original references for data included in this compilation, is available in Table S1 & S2. Provided in each site-specific sheet are the: 1) Depth of Tie Point Age (cm), Tie Point Age (yr), and Tie Point Uncertainty (yr, where tie point age uncertainty was derived from interpolating the basin reference core [see 'Reference Core Tie Points'] Speleo-Age uncertainty estimated from Barker et al. (2011)); 2) (if applicable) the HadSST1.1-derived bias correction magnitude (in °C, see all corrections listed by latitude in 'HadSST & SynTrACE Bias Estimate'), the uncertainty on this bias, the original reference transfer function uncertainty (for Foraminiferal [Foram], Rad [Radiolarian], or Cocc [Coccolithophore]-based transfer functions), and the estimated sum of the squared bias & TF uncertainties used to perturb the SST record; 3) the core site benthic oxygen isotope record on the depth scale that was used to align the record to the basin reference oxygen isotope record; 4) the published SST reconstruction(s) on the depth scale (may be >1), labeled as Depth (cm), Proxy SST, where Proxy can be Foram (foraminiferal transfer function), Cocc (coccolithophore TF), Rad (radiolarian TF), Mg/Ca (in mmol/mol where reported), or UK37 (in unsaturation ratio where reported). If a bias correction was applied, those records include another column "Proxy SST_biascorr"; 5) the SST & age uncertainty-perturbed SST reconstruction(s) at 100-yr resolution, listed as Age (yr), Proxy SST -2sd, Proxy SST mean, Proxy SST +2sd.

Sheet M23323-1_UK37
A1: ID | B1: Longitude | C1: Latitude | D1: Proxy | E1: Tie Point Depth (cm) | F1: Tie Point Age (yr) | G1: Tie Point Uncertainty (yr) | H1: Hadley Bias Correction | I1: Hadley uncertainty | J1: TF Uncertainty | K1: SS Uncertainty | L1: Benthic d18O Depth (cm) | M1: Benthic d18O (per mil) | N1: Depth (cm) | O1: Proxy Value | P1: SST (ºC) | Q1: Biascorr | R1: Age (yr) | S1: SST -2sd | T1: SST mean | U1: SST +2sd
A2: M23323-1 | B2: 5.92 | C2: 67.77 | D2: UK37 | E2: 732 | F2: 111224 | G2: 1600 | L2: 720.5 | M2: 5.04 | N2: 755.5 | P2: 10.284 | R2: 115000 | S2: 0.92806703 | T2: 3.8915374 | U2: 7.6767893
E3: 759 | F3: 118724 | G3: 1520 | L3: 721.5 | M3: 5.052 | N3: 760.5 | P3: 10.679 | R3: 115100 | S3: 0.92539786 | T3: 4.1027872 | U3: 7.9635344
E4: 867 | F4: 128048 | G4: 1418 | L4: 722.5 | M4: 5.05 | N4: 762.5 | P4: 10.355 | R4: 115200 | S4: 1.0823852 | T4: 4.0470135 | U4: 8.1363837
E5: 906 | F5: 136383 | G5: 1304 | L5: 723.5 | M5: 5.07 | N5: 765.5 | P5: 9.572 | R5: 115300 | S5: 0.92612751 | T5: 4.0018915 | U5: 7.7778487
L6: 724.5 | M6: 5.11 | N6: 767.5 | P6: 9.69 | R6: 115400 | S6: 0.76248978 | T6: 3.9843612 | U6: 8.3597232
L7: 725.5 | M7: 5.05 | N7: 770.5 | P7: 9.754 | R7: 115500 | S7: 1.0223981 | T7: 3.9406218 | U7: 8.0267587
L8: 726.5 | M8: 5.03 | N8: 775.5 | P8: 10.299 | R8: 115600 | S8: 0.69557974 | T8: 3.9831609 | U8: 8.5222807
L9: 727.5 | M9: 4.99 | N9: 777.5 | P9: 10.823 | R9: 115700 | S9: 0.91591227 | T9: 3.9620968 | U9: 8.4441142
L10: 728.5 | M10: 5.01 | N10: 780.5 | P10: 10.367 | R10: 115800 | S10: 1.112931 | T10: 3.9859426 | U10: 8.7106124
L11: 729.5 | M11: 4.99 | N11: 782.5 | P11: 11.964 | R11: 115900 | S11: 1.0666296 | T11: 3.9904232 | U11: 8.8953314
L12: 730.5 | M12: 4.87 | N12: 785.5 | P12: 10.44 | R12: 116000 | S12: 1.2832406 | T12: 4.0527225 | U12: 9.384574
L13: 731.5 | M13: 5.2 | N13: 787.5 | P13: 11.718 | R13: 116100 | S13: 1.2854331 | T13: 3.9603747 | U13: 9.2454896
L14: 732.5 | M14: 5.11 | N14: 790.5 | P14: 11.033 | R14: 116200 | S14: 1.3219783 | T14: 4.0178893 | U14: 9.2018396
L15: 733.5 | M15: 4.93 | N15: 792.5 | P15: 10.236 | R15: 116300 | S15: 1.2549021 | T15: 4.0300964 | U15: 9.1176036
L16: 734.5 | M16: 5.04 | N16: 798.5 | P16: 12.462 | R16: 116400 | S16: 1.1814951 | T16: 4.0916194 | U16: 9.2604693
L17: 735.5 | M17: 5.02 | N17: 800.5 | P17: 11.086 | R17: 116500 | S17: 1.2485316 | T17: 4.1519201 | U17: 9.59023
... L49: 767.5 | M49: 4.4 | N49: 850.5 | P49: 9.372 | R49: 119700 | S49: 2.5945731 | T49: 7.6514466 | U49: 11.097584
L50: 768.5 | M50: 4.36 | R50: 119800 | S50: 2.8027717 | T50: 7.8027265 | U50: 11.35931
L51: 769.5 | M51: 4.38 | R51: 119900 | S51: 2.9002016 | T51: 7.8662655 | U51: 11.340682
L52: 770.5 | M52: 4.39 | R52: 120000 | S52: 3.1101714 | T52: 7.8695897 | U52: 11.357215
L53: 771.5 | M53: 4.39 | R53: 120100 | S53: 3.1904542 | T53: 8.044091 | U53: 11.202645
L54: 772.5 | M54: 4.45 | R54: 120200 | S54: 3.2974959 | T54: 8.058109 | U54: 11.276466
L55: 773.5 | M55: 4.38 | R55: 120300 | S55: 3.3673707 | T55: 8.1006026 | U55: 11.381033
L56: 774.5 | M56: 4.31 | R56: 120400 | S56: 3.3125166 | T56: 8.1952591 | U56: 11.555465
L57: 775.5 | M57: 4.37 | R57: 120500 | S57: 3.3920152 | T57: 8.2368203 | U57: 11.311891
L58: 776.5 | M58: 4.36 | R58: 120600 | S58: 3.4014095 | T58: 8.3650433 | U58: 11.48919
L59: 777.5 | M59: 4.39 | R59: 120700 | S59: 3.5044975 | T59: 8.4674495 | U59: 11.389976
L60: 778.5 | M60: 4.35 | R60: 120800 | S60: 3.6785283 | T60: 8.4647141 | U60: 11.396344
L61: 779.5 | M61: 4.46 | R61: 120900 | S61: 3.8890307 | T61: 8.3875272 | U61: 11.18355
... L152: 876.5 | M152: 3.31 | R152: 130000 | S152: 0.14018602 | T152: 2.6927002 | U152: 5.8037064
L153: 877.5 | M153: 3.58
L154: 878.5 | M154: 3.39
L155: 879.5 | M155: 3.41
L156: 880.5 | M156: 3.44
L157: 881.5 | M157: 3.74
L158: 882.5 | M158: 3.69
L159: 883.5 | M159: 3.9
L160: 884.5 | M160: 4.12
L161: 885.5 | M161: 4.23
...

Sheet M23323-1_Foram
A1: ID | B1: Longitude | C1: Latitude | D1: Proxy | E1: Tie Point Depth (cm) | F1: Tie Point Age (yr) | G1: Tie Point Uncertainty (yr) | H1: Hadley Bias Correction | I1: Hadley uncertainty | J1: TF Uncertainty | K1: SS Uncertainty | L1: Benthic d18O Depth (cm) | M1: Benthic d18O (per mil) | N1: Depth (cm) | O1: Proxy Value | P1: SST (ºC) | Q1: Biascorr | R1: Age (yr) | S1: SST -2sd | T1: SST mean | U1: SST +2sd
A2: M23323-1 | B2: 5.92 | C2: 67.77 | D2: Foram | E2: 732 | F2: 111224 | G2: 1600 | L2: 720.5 | M2: 5.04 | N2: 750.5 | P2: 3.1 | R2: 115000 | S2: 7.9099448 | T2: 10.205466 | U2: 12.667878
E3: 759 | F3: 118724 | G3: 1520 | L3: 721.5 | M3: 5.052 | N3: 751.5 | P3: 2.8 | R3: 115100 | S3: 8.0769308 | T3: 10.243602 | U3: 12.7327
E4: 867 | F4: 128048 | G4: 1418 | L4: 722.5 | M4: 5.05 | N4: 752.5 | P4: 3.2 | R4: 115200 | S4: 7.7818319 | T4: 10.280521 | U4: 12.942564
E5: 906 | F5: 136383 | G5: 1304 | L5: 723.5 | M5: 5.07 | N5: 753.5 | P5: 3.7 | R5: 115300 | S5: 7.8747601 | T5: 10.263443 | U5: 12.63353
L6: 724.5 | M6: 5.11 | N6: 754.5 | P6: 4.2 | R6: 115400 | S6: 7.8169983 | T6: 10.306473 | U6: 12.630553
L7: 725.5 | M7: 5.05 | N7: 755.5 | P7: 4.5 | R7: 115500 | S7: 7.9299992 | T7: 10.360334 | U7: 12.698419
L8: 726.5 | M8: 5.03 | N8: 756.5 | P8: 4 | R8: 115600 | S8: 7.9125076 | T8: 10.387562 | U8: 12.745713
L9: 727.5 | M9: 4.99 | N9: 757.5 | P9: 5 | R9: 115700 | S9: 7.7369199 | T9: 10.431951 | U9: 12.726827
L10: 728.5 | M10: 5.01 | N10: 758.5 | P10: 6.4 | R10: 115800 | S10: 7.8811649 | T10: 10.413885 | U10: 12.68426
L11: 729.5 | M11: 4.99 | N11: 759.5 | P11: 5.7 | R11: 115900 | S11: 8.1850765 | T11: 10.360939 | U11: 12.809948
L12: 730.5 | M12: 4.87 | N12: 760.5 | P12: 7.9 | R12: 116000 | S12: 7.9167445 | T12: 10.380019 | U12: 12.793567
L13: 731.5 | M13: 5.2 | N13: 761.5 | P13: 7.8 | R13: 116100 | S13: 7.9640484 | T13: 10.40907 | U13: 12.715773
L14: 732.5 | M14: 5.11 | N14: 762.5 | P14: 8.1 | R14: 116200 | S14: 7.954172 | T14: 10.379265 | U14: 12.689329
L15: 733.5 | M15: 4.93 | N15: 763.5 | P15: 7.8 | R15: 116300 | S15: 7.8908948 | T15: 10.340295 | U15: 12.860557
L16: 734.5 | M16: 5.04 | N16: 764.5 | P16: 6.7 | R16: 116400 | S16: 7.8781527 | T16: 10.35876 | U16: 12.86045
L17: 735.5 | M17: 5.02 | N17: 765.5 | P17: 7.2 | R17: 116500 | S17: 7.9064655 | T17: 10.35298 | U17: 12.860713
... L152: 876.5 | M152: 3.31 | N152: 900.5 | P152: 2.7 | R152: 130000 | S152: 6.4660439 | T152: 9.4714331 | U152: 13.166984
L153: 877.5 | M153: 3.58 | N153: 901.5 | P153: 2.1
L154: 878.5 | M154: 3.39 | N154: 902.5 | P154: 2.4
L155: 879.5 | M155: 3.41 | N155: 903.5 | P155: 2.9
L156: 880.5 | M156: 3.44 | N156: 904.5 | P156: 3.2
L157: 881.5 | M157: 3.74 | N157: 905.5 | P157: 1.2
L158: 882.5 | M158: 3.69 | N158: 907.5 | P158: 2.4
L159: 883.5 | M159: 3.9 | N159: 908.5 | P159: 2.2
L160: 884.5 | M160: 4.12 | N160: 909.5 | P160: 2.5
L161: 885.5 | M161: 4.23 | N161: 910.5 | P161: 2.7
L162: 886.5 | M162: 2.26 | N162: 911.5 | P162: 4.6
L163: 887.5 | M163: 1.78 | N163: 912.5 | P163: 4
L164: 888.5 | M164: 3.31 | N164: 913.5 | P164: 3.2
... L178: 902.5 | M178: 4.95 | N178: 927.5 | P178: 2.1
L179: 903.5 | M179: 5.05
L180: 904.5 | M180: 5.05
L181: 905.5 | M181: 5.07
L182: 907.5 | M182: 4.84
L183: 908.5 | M183: 4.9
L184: 909.5 | M184: 4.88
L185: 910.5 | M185: 4.77
L186: 913.5 | M186: 4.73
L187: 914.5 | M187: 4.63
...

Sheet V28-14
A1: ID | B1: Longitude | C1: Latitude | D1: Proxy | E1: Tie Point Depth (cm) | F1: Tie Point Age (yr) | G1: Tie Point Uncertainty (yr) | H1: Hadley Bias Correction | I1: Hadley uncertainty | J1: TF Uncertainty | K1: SS Uncertainty | L1: Benthic d18O Depth (cm) | M1: Benthic d18O (per mil) | N1: Depth (cm) | O1: Proxy Value | P1: SST (ºC) | Q1: Biascorr | R1: Age (yr) | S1: SST -2sd | T1: SST mean | U1: SST +2sd
A2: V28-14 | B2: -29.57 | C2: 64.78 | D2: Foram | E2: 505 | F2: 118987 | G2: 1517 | H2: ='HadSST & SynTrACE Bias Estimate'!D2 -> 0.63546515 | I2: ='HadSST & SynTrACE Bias Estimate'!E2 -> 0.19461474 | J2: 1.4 | K2: =SQRT(I2^2+J2^2) -> 1.413462 | L2: 501 | M2: 4.14 | N2: 480 | P2: 3.1 | Q2: =N2-$A$8 -> 480 | R2: 115000 | S2: 1.7142948 | T2: 4.9274488 | U2: 8.8078343
E3: 525 | F3: 127212 | G3: 1427 | L3: 505 | M3: 3.71 | N3: 485 | P3: 3.1 | Q3: =N3-$A$8 -> 485 | R3: 115100 | S3: 1.6942992 | T3: 4.9945437 | U3: 8.8496626
E4: 545 | F4: 136383 | G4: 1304 | L4: 511 | M4: 3.22 | N4: 490 | P4: 3.85 | Q4: =N4-$A$8 -> 490 | R4: 115200 | S4: 1.6774117 | T4: 5.0405101 | U4: 8.9084297
L5: 515 | M5: 3.2 | N5: 495 | P5: 4.2 | Q5: =N5-$A$8 -> 495 | R5: 115300 | S5: 1.7544819 | T5: 5.1105939 | U5: 8.9992763
L6: 519 | M6: 3.22 | N6: 500 | P6: 5.7 | Q6: =N6-$A$8 -> 500 | R6: 115400 | S6: 1.7330597 | T6: 5.1954928 | U6: 9.0453893
L7: 525 | M7: 3.25 | N7: 505 | P7: 8.8 | Q7: =N7-$A$8 -> 505 | R7: 115500 | S7: 1.7655378 | T7: 5.282586 | U7: 9.092968
L8: 535 | M8: 3.67 | N8: 510 | P8: 10.95 | Q8: =N8-$A$8 -> 510 | R8: 115600 | S8: 1.7971753 | T8: 5.3652901 | U8: 9.1732734
L9: 539 | M9: 4.62 | N9: 515 | P9: 10.6 | Q9: =N9-$A$8 -> 515 | R9: 115700 | S9: 1.8765634 | T9: 5.4276703 | U9: 9.2514326
L10: 545 | M10: 5.1 | N10: 520 | P10: 11.05 | Q10: =N10-$A$8 -> 520 | R10: 115800 | S10: 1.8849065 | T10: 5.4952237 | U10: 9.310515
N11: 525 | P11: 9.35 | Q11: =N11-$A$8 -> 525 | R11: 115900 | S11: 1.9259391 | T11: 5.5933702 | U11: 9.3960948
N12: 530 | P12: 4.95 | Q12: =N12-$A$8 -> 530 | R12: 116000 | S12: 1.9592604 | T12: 5.6640781 | U12: 9.4718139
N13: 535 | P13: 3.2 | Q13: =N13-$A$8 -> 535 | R13: 116100 | S13: 1.9815929 | T13: 5.7478183 | U13: 9.5221662
N14: 540 | P14: 3.2 | Q14: =N14-$A$8 -> 540 | R14: 116200 | S14: 2.0223039 | T14: 5.8415579 | U14: 9.5633788
N15: 545 | P15: 3.2 | Q15: =N15-$A$8 -> 545 | R15: 116300 | S15: 2.0813249 | T15: 5.9256082 | U15: 9.6054428
N16: 550 | P16: 5.45 | Q16: =N16-$A$8 -> 550 | R16: 116400 | S16: 2.1002656 | T16: 6.0347176 | U16: 9.7102132
N17: 555 | P17: 3.2 | Q17: =N17-$A$8 -> 555 | R17: 116500 | S17: 2.1239844 | T17: 6.1473353 | U17: 9.8304566
N18: 560 | P18: 3.3 | Q18: =N18-$A$8 -> 560 | R18: 116600 | S18: 2.1103658 | T18: 6.2620201 | U18: 9.8889297
R19: 116700 | S19: 2.2730656 | T19: 6.3583014 | U19: 10.027345
R20: 116800 | S20: 2.3021198 | T20: 6.4329499 | U20: 10.128303
R21: 116900 | S21: 2.3702252 | T21: 6.5166701 | U21: 10.196951
R22: 117000 | S22: 2.3836246 | T22: 6.5898695 | U22: 10.274373
R23: 117100 | S23: 2.3558324 | T23: 6.6664168 | U23: 10.335472
R24: 117200 | S24: 2.4657051 | T24: 6.7529063 | U24: 10.399168
R25: 117300 | S25: 2.4948744 | T25: 6.8493176 | U25: 10.485834
R26: 117400 | S26: 2.5449483 | T26: 6.9397793 | U26: 10.556023
R27: 117500 | S27: 2.6227509 | T27: 7.0213971 | U27: 10.643189
R28: 117600 | S28: 2.5673083 | T28: 7.1301775 | U28: 10.70234
R29: 117700 | S29: 2.695285 | T29: 7.2055252 | U29: 10.772142
R30: 117800 | S30: 2.7457082 | T30: 7.3026441 | U30: 10.820846
... R152: 130000 | S152: 1.351747 | T152: 4.5820608 | U152: 9.1023051

Sheet EW9302-JPC8
A1: ID | B1: Longitude | C1: Latitude | D1: Proxy | E1: Tie Point Depth (cm) | F1: Tie Point Age (yr) | G1: Tie Point Uncertainty (yr) | H1: Hadley Bias Correction | I1: Hadley uncertainty | J1: TF Uncertainty | K1: SS Uncertainty | L1: Benthic d18O Depth (cm) | M1: Benthic d18O (per mil) | N1: Depth (cm) | O1: Proxy Value | P1: SST (ºC) | Q1: Biascorr | R1: Age (yr) | S1: SST -2sd | T1: SST mean | U1: SST +2sd
A2: EW9302-JPC8 | B2: -25 | C2: 61.42 | D2: Foram | E2: 864 | F2: 112903 | G2: 1583 | L2: 504 | M2: 3.547 | N2: 876 | P2: 10.4 | R2: 115000 | S2: 5.1288501 | T2: 9.6494307 | U2: 13.198928
E3: 933 | F3: 118720 | G3: 1520 | L3: 512 | M3: 3.642 | N3: 880 | P3: 5.8 | R3: 115100 | S3: 5.0238742 | T3: 9.7460537 | U3: 13.422913
E4: 1148 | F4: 127204 | G4: 1427 | L4: 520 | M4: 3.337 | N4: 888 | P4: 8.2 | R4: 115200 | S4: 5.3136317 | T4: 9.8604225 | U4: 13.458285
E5: 1182 | F5: 132142 | G5: 1361 | L5: 528 | M5: 4.1375 | N5: 896 | P5: 10.3 | R5: 115300 | S5: 5.3297965 | T5: 9.9905274 | U5: 13.494224
E6: 1196 | F6: 136383 | G6: 1304 | L6: 536 | M6: 3.977 | N6: 904 | P6: 11.6 | R6: 115400 | S6: 5.2781537 | T6: 10.09436 | U6: 13.415275
E7: 1247 | F7: 139428 | G7: 1333 | L7: 544 | M7: 4.042 | N7: 912 | P7: 11.6 | R7: 115500 | S7: 5.3265751 | T7: 10.123013 | U7: 13.433309
L8: 552 | M8: 4.145 | N8: 920 | P8: 11.1 | R8: 115600 | S8: 5.4282593 | T8: 10.214371 | U8: 13.455051
L9: 559 | M9: 4.051 | N9: 928 | P9: 11.3 | R9: 115700 | S9: 5.406848 | T9: 10.338612 | U9: 13.494787
L10: 568 | M10: 3.643 | N10: 936 | P10: 12.8 | R10: 115800 | S10: 5.4366776 | T10: 10.458701 | U10: 13.556998
L11: 584 | M11: 3.645 | N11: 944 | P11: 12.5 | R11: 115900 | S11: 5.6905871 | T11: 10.522096 | U11: 13.6437
L12: 592 | M12: 3.708 | N12: 952 | P12: 12.6 | R12: 116000 | S12: 5.7380033 | T12: 10.605297 | U12: 13.760452
L13: 616 | M13: 3.49 | N13: 960 | P13: 12.1 | R13: 116100 | S13: 5.7897795 | T13: 10.711044 | U13: 13.743025
L14: 624 | M14: 3.574 | N14: 968 | P14: 11.7 | R14: 116200 | S14: 5.8465795 | T14: 10.770965 | U14: 13.779732
L15: 632 | M15: 3.5135 | N15: 976 | P15: 13.1 | R15: 116300 | S15: 5.8153111 | T15: 10.859887 | U15: 13.859023
L16: 640 | M16: 3.487 | N16: 984 | P16: 13.6 | R16: 116400 | S16: 6.0126274 | T16: 10.97755 | U16: 13.987912
L17: 648 | M17: 3.4065 | N17: 992 | P17: 13.5 | R17: 116500 | S17: 6.2514872 | T17: 11.075833 | U17: 13.991363
L18: 656 | M18: 3.311 | N18: 1000 | P18: 13.6 | R18: 116600 | S18: 6.3468367 | T18: 11.172221 | U18: 14.066632
L19: 664 | M19: 3.318 | N19: 1008 | P19: 14 | R19: 116700 | S19: 6.4080688 | T19: 11.242773 | U19: 14.001571
... L43: 888 | M43: 3.144 | N43: 1176 | P43: 8.2 | R43: 119100 | S43: 9.3806986 | T43: 12.374243 | U43: 15.825959
L44: 904 | M44: 3.041 | R44: 119200 | S44: 9.4724077 | T44: 12.389006 | U44: 15.783872
L45: 912 | M45: 2.912 | R45: 119300 | S45: 9.3723805 | T45: 12.435538 | U45: 15.762638
L46: 944 | M46: 2.642 | R46: 119400 | S46: 9.4768297 | T46: 12.505236 | U46: 15.795529
L47: 952 | M47: 2.611 | R47: 119500 | S47: 9.6093918 | T47: 12.545683 | U47: 15.855114
L48: 968 | M48: 2.472 | R48: 119600 | S48: 9.5964413 | T48: 12.61139 | U48: 15.932513
L49: 1000 | M49: 2.533 | R49: 119700 | S49: 9.6341026 | T49: 12.633385 | U49: 15.956522
L50: 1024 | M50: 2.542 | R50: 119800 | S50: 9.7171676 | T50: 12.739028 | U50: 16.018425
L51: 1040 | M51: 2.63 | R51: 119900 | S51: 9.9101594 | T51: 12.771106 | U51: 16.085775
L52: 1048 | M52: 2.446 | R52: 120000 | S52: 9.8222241 | T52: 12.797526 | U52: 16.24203
L53: 1052 | M53: 2.339 | R53: 120100 | S53: 9.9289078 | T53: 12.82923 | U53: 16.222265
L54: 1064 | M54: 2.374 | R54: 120200 | S54: 10.013472 | T54: 12.911429 | U54: 16.219046
L55: 1072 | M55: 2.508 | R55: 120300 | S55: 9.9796025 | T55: 12.927644 | U55: 16.187944
... L85: 1248 | M85: 4.386 | R85: 123300 | S85: 11.105562 | T85: 14.191613 | U85: 17.214781
R86: 123400 | S86: 11.113527 | T86: 14.252608 | U86: 16.998733
R87: 123500 | S87: 11.040781 | T87: 14.222721 | U87: 17.114111
R88: 123600 | S88: 10.978603 | T88: 14.198917 | U88: 17.110851
R89: 123700 | S89: 11.000341 | T89: 14.196353 | U89: 17.147591
R90: 123800 | S90: 10.99416 | T90: 14.247054 | U90: 17.046545
R91: 123900 | S91: 11.009221 | T91: 14.190674 | U91: 17.019049
R92: 124000 | S92: 11.015448 | T92: 14.173201 | U92: 17.02237
...

Sheet ODP 980
A1: ID | B1: Longitude | C1: Latitude | D1: Proxy | E1: Tie Point Depth (cm) | F1: Tie Point Age (yr) | G1: Tie Point Uncertainty (yr) | H1: Hadley Bias Correction | I1: Hadley uncertainty | J1: TF Uncertainty | K1: SS Uncertainty | L1: Benthic d18O Depth (cm) | M1: Benthic d18O (per mil) | N1: Depth (cm) | O1: Proxy Value | P1: SST (ºC) | Q1: Biascorr | R1: Age (yr) | S1: SST -2sd | T1: SST mean | U1: SST +2sd
A2: ODP 980 | B2: -14.7 | C2: 55.48 | D2: Foram | E2: 1367 | F2: 105349 | G2: 1234 | L2: 1309.5 | M2: 4.2 | N2: 1421 | P2: 12.39 | R2: 115000 | S2: 9.4262805 | T2: 12.185399 | U2: 15.20281
E3: 1407 | F3: 111246 | G3: 1600 | L3: 1314.5 | M3: 4.01 | N3: 1422 | P3: 12.68 | R3: 115100 | S3: 9.3433105 | T3: 12.183075 | U3: 15.132635
E4: 1472 | F4: 118701 | G4: 1520 | L4: 1321.5 | M4: 4.08 | N4: 1425 | P4: 12.37 | R4: 115200 | S4: 9.209021 | T4: 12.196109 | U4: 15.121036
E5: 1732 | F5: 127212 | G5: 1427 | L5: 1327 | M5: 4 | N5: 1429 | P5: 12.445 | R5: 115300 | S5: 9.2600797 | T5: 12.174598 | U5: 15.100493
E6: 1785 | F6: 136361 | G6: 1304 | L6: 1332 | M6: 4.08 | N6: 1431 | P6: 12.39 | R6: 115400 | S6: 9.2541151 | T6: 12.135401 | U6: 15.014315
E7: 1867 | F7: 139396 | G7: 1333 | L7: 1337 | M7: 3.92 | N7: 1432 | P7: 12.39 | R7: 115500 | S7: 9.2473587 | T7: 12.122604 | U7: 15.131923
L8: 1341.5 | M8: 4.11 | N8: 1436 | P8: 12.39 | R8: 115600 | S8: 9.2081988 | T8: 12.173634 | U8: 15.018803
L9: 1347 | M9: 4.2 | N9: 1437 | P9: 12 | R9: 115700 | S9: 9.2619219 | T9: 12.154563 | U9: 15.03197
L10: 1354.5 | M10: 3.96 | N10: 1444 | P10: 12.04 | R10: 115800 | S10: 9.2466211 | T10: 12.193385 | U10: 15.04595
L11: 1357 | M11: 4 | N11: 1446 | P11: 12.11 | R11: 115900 | S11: 9.2991049 | T11: 12.195245 | U11: 15.236104
L12: 1367 | M12: 4.47 | N12: 1450 | P12: 12.04 | R12: 116000 | S12: 9.3405474 | T12: 12.209385 | U12: 15.226102
L13: 1372 | M13: 4.42 | N13: 1454 | P13: 12.28 | R13: 116100 | S13: 9.3155097 | T13: 12.22131 | U13: 15.094148
L14: 1377 | M14: 4.23 | N14: 1459 | P14: 11.92 | R14: 116200 | S14: 9.2180111 | T14: 12.190881 | U14: 15.303778
L15: 1381.5 | M15: 4.15 | N15: 1461 | P15: 12.28 | R15: 116300 | S15: 9.2390163 | T15: 12.193779 | U15: 15.278805
L16: 1387 | M16: 4.01 | N16: 1466 | P16: 12.28 | R16: 116400 | S16: 9.323659 | T16: 12.165665 | U16: 15.196956
L17: 1392 | M17: 4.12 | N17: 1470 | P17: 12.28 | R17: 116500 | S17: 9.339857 | T17: 12.215503 | U17: 15.261403
L18: 1397 | M18: 4.18 | N18: 1474 | P18: 12.19 | R18: 116600 | S18: 9.3606999 | T18: 12.20617 | U18: 15.421239
L19: 1401.5 | M19: 4.4 | N19: 1476 | P19: 12.28 | R19: 116700 | S19: 9.3359436 | T19: 12.221852 | U19: 15.234671
... L89: 1867 | M89: 5.38 | N89: 1780 | P89: 8 | R89: 123700 | S89: 11.513822 | T89: 15.037458 | U89: 18.267295
L90: 1874 | M90: 5.31 | R90: 123800 | S90: 11.697962 | T90: 15.141966 | U90: 18.215181
L91: 1881 | M91: 5.355 | R91: 123900 | S91: 11.738052 | T91: 15.16321 | U91: 18.360318
R92: 124000 | S92: 11.667159 | T92: 15.198763 | U92: 18.255951
R93: 124100 | S93: 11.55285 | T93: 15.168295 | U93: 18.331049
R94: 124200 | S94: 11.659585 | T94: 15.10288 | U94: 18.32893
R95: 124300 | S95: 11.773732 | T95: 15.175048 | U95: 18.317187
R96: 124400 | S96: 11.833731 | T96: 15.17882 | U96: 18.331726
R97: 124500 | S97: 11.858303 | T97: 15.204893 | U97: 18.363371
R98: 124600 | S98: 11.847553 | T98: 15.139374 | U98: 18.367813
R99: 124700 | S99: 11.618897 | T99: 15.127958 | U99: 18.39476
R100: 124800 | S100: 11.805282 | T100: 15.131776 | U100: 18.384665
R101: 124900 | S101: 11.907816 | T101: 15.136266 | U101: 18.415995
R102: 125000 | S102: 11.742748 | T102: 15.175733 | U102: 18.325913
R103: 125100 | S103: 11.659653 | T103: 15.170888 | U103: 18.284083
... R152: 130000 | S152: 3.0704544 | T152: 6.7603248 | U152: 15.729458

Sheet NA87-25
A1: ID | B1: Longitude | C1: Latitude | D1: Proxy | E1: Tie Point Depth (cm) | F1: Tie Point Age (yr) | G1: Tie Point Uncertainty (yr) | H1: Hadley Bias Correction | I1: Hadley uncertainty | J1: TF Uncertainty | K1: SS Uncertainty | L1: Benthic d18O Depth (cm) | M1: Benthic d18O (per mil) | N1: Depth (cm) | O1: Proxy Value | P1: SST (ºC) | Q1: Biascorr | R1: Age (yr) | S1: SST -2sd | T1: SST mean | U1: SST +2sd
A2: NA87-25 | B2: -14.73 | C2: 55.18 | D2: Foram | E2: 617 | F2: 118732 | G2: 1520 | L2: 610.5 | M2: 3.63 | N2: 610.5 | P2: 13.2 | R2: 115000 | S2: 11.375336 | T2: 13.228096 | U2: 16.031954
E3: 724 | F3: 127212 | G3: 1427 | L3: 614 | M3: 3.74 | N3: 614 | P3: 13.8 | R3: 115100 | S3: 11.301209 | T3: 13.227633 | U3: 15.851247
E4: 769 | F4: 136361 | G4: 1304 | L4: 615.5 | M4: 3.63 | N4: 615.5 | P4: 13 | R4: 115200 | S4: 11.220982 | T4: 13.383879 | U4: 15.861397
L5: 620.5 | M5: 3.48 | N5: 620.5 | P5: 13.2 | R5: 115300 | S5: 11.324867 | T5: 13.417326 | U5: 15.814678
L6: 625.5 | M6: 3.45 | N6: 624 | P6: 13.9 | R6: 115400 | S6: 11.436725 | T6: 13.490047 | U6: 15.731848
L7: 634 | M7: 3.35 | N7: 625.5 | P7: 13.4 | R7: 115500 | S7: 11.591591 | T7: 13.565913 | U7: 15.985314
L8: 635.5 | M8: 3.5 | N8: 630.5 | P8: 13.6 | R8: 115600 | S8: 11.531678 | T8: 13.517235 | U8: 16.001248
L9: 640.5 | M9: 3.37 | N9: 634 | P9: 14.2 | R9: 115700 | S9: 11.627186 | T9: 13.52272 | U9: 15.890387
L10: 644 | M10: 3.36 | N10: 635.5 | P10: 14.3 | R10: 115800 | S10: 11.342364 | T10: 13.571398 | U10: 15.794779
L11: 645 | M11: 3.42 | N11: 640.5 | P11: 13.8 | R11: 115900 | S11: 11.388405 | T11: 13.578953 | U11: 15.866983
L12: 654 | M12: 3.23 | N12: 644 | P12: 15.1 | R12: 116000 | S12: 11.322923 | T12: 13.460404 | U12: 15.757851
L13: 656.5 | M13: 3.24 | N13: 645 | P13: 14.3 | R13: 116100 | S13: 11.243169 | T13: 13.551987 | U13: 16.160884
L14: 661.5 | M14: 3.21 | N14: 654 | P14: 13.4 | R14: 116200 | S14: 11.145331 | T14: 13.413948 | U14: 16.071504
L15: 664 | M15: 3.25 | N15: 656.5 | P15: 13.4 | R15: 116300 | S15: 11.286815 | T15: 13.306068 | U15: 15.762811
L16: 666.5 | M16: 3.21 | N16: 661.5 | P16: 13.8 | R16: 116400 | S16: 10.813123 | T16: 13.356595 | U16: 15.908378
... L53: 805 | M53: 5 | N53: 795 | P53: 11.5 | R53: 120100 | S53: 11.108241 | T53: 13.741139 | U53: 16.374174
N54: 799 | P54: 10.9 | R54: 120200 | S54: 11.124079 | T54: 13.722617 | U54: 16.451468
N55: 805 | P55: 9.1 | R55: 120300 | S55: 11.253301 | T55: 13.768542 | U55: 16.356566
R56: 120400 | S56: 11.183344 | T56: 13.769292 | U56: 16.383743
R57: 120500 | S57: 11.16224 | T57: 13.79197 | U57: 16.366057
R58: 120600 | S58: 11.157904 | T58: 13.792946 | U58: 16.419206
R59: 120700 | S59: 11.190443 | T59: 13.828228 | U59: 16.318263
R60: 120800 | S60: 11.090344 | T60: 13.870797 | U60: 16.41037
R61: 120900 | S61: 11.114614 | T61: 13.872053 | U61: 16.47981
R62: 121000 | S62: 11.34273 | T62: 13.948532 | U62: 16.446102
R63: 121100 | S63: 11.453056 | T63: 13.952755 | U63: 16.577348
R64: 121200 | S64: 11.361943 | T64: 13.866418 | U64: 16.502819
R65: 121300 | S65: 11.363927 | T65: 13.923179 | U65: 16.588517
R66: 121400 | S66: 11.294477 | T66: 13.931939 | U66: 16.689546
R67: 121500 | S67: 11.327771 | T67: 13.940499 | U67: 16.593525
... R152: 130000 | S152: 8.5715925 | T152: 13.369303 | U152: 17.076669

Sheet V27-20
A1: ID | B1: Longitude | C1: Latitude | D1: Proxy | E1: Tie Point Depth (cm) | F1: Tie Point Age (yr) | G1: Tie Point Uncertainty (yr) | H1: Hadley Bias Correction | I1: Hadley uncertainty | J1: TF Uncertainty | K1: SS Uncertainty | L1: Benthic d18O Depth (cm) | M1: Benthic d18O (per mil) | N1: Depth (cm) | O1: Proxy Value | P1: SST (ºC) | Q1: Biascorr | R1: Age (yr) | S1: SST -2sd | T1: SST mean | U1: SST +2sd
A2: V27-20 | B2: -46.2 | C2: 54 | D2: Foram | E2: 454 | F2: 111255 | G2: 1600 | H2: ='HadSST & SynTrACE Bias Estimate'!D3 -> 0.60381848 | I2: ='HadSST & SynTrACE Bias Estimate'!E3 -> 0.22203267 | J2: 1.4 | K2: =SQRT(J2^2+I2^2) -> 1.4174973 | L2: 414 | M2: 3.105 | N2: 429 | P2: 6.5 | Q2: 5.8961815 | R2: 115000 | S2: 5.0039653 | T2: 7.8290789 | U2: 11.804327
E3: 499 | F3: 127190 | G3: 1427 | L3: 419 | M3: 3.51 | N3: 434 | P3: 6.7 | Q3: 6.0961815 | R3: 115100 | S3: 5.000938 | T3: 7.8911762 | U3: 11.894751
E4: 512 | F4: 131706 | G4: 1368 | L4: 424 | M4: 3.58 | N4: 438 | P4: 6.3 | Q4: 5.6961815 | R4: 115200 | S4: 5.0097377 | T4: 7.9291981 | U4: 11.869609
E5: 519 | F5: 136317 | G5: 1303 | L5: 429 | M5: 3.61 | N5: 444 | P5: 7.1 | Q5: 6.4961815 | R5: 115300 | S5: 5.0110034 | T5: 7.9693709 | U5: 11.887119
L6: 438 | M6: 3.74 | N6: 449 | P6: 8 | Q6: 7.3961815 | R6: 115400 | S6: 5.0133532 | T6: 8.0134963 | U6: 11.902206
L7: 454 | M7: 4.09 | N7: 454 | P7: 8.2 | Q7: 7.5961815 | R7: 115500 | S7: 5.0288576 | T7: 8.0452656 | U7: 11.882239
L8: 459 | M8: 3.96 | N8: 459 | P8: 7.1 | Q8: 6.4961815 | R8: 115600 | S8: 5.0932123 | T8: 8.0900339 | U8: 11.882413
L9: 464 | M9: 3.2 | N9: 464 | P9: 7.8 | Q9: 7.1961815 | R9: 115700 | S9: 5.0712371 | T9: 8.1399338 | U9: 11.862863
L10: 474 | M10: 3.39 | N10: 469 | P10: 9 | Q10: 8.3961815 | R10: 115800 | S10: 5.079278 | T10: 8.1996893 | U10: 11.902566
L11: 479 | M11: 3.13 | N11: 474 | P11: 10.8 | Q11: 10.196182 | R11: 115900 | S11: 5.191374 | T11: 8.2381492 | U11: 11.959035
L12: 484 | M12: 3.065 | N12: 479 | P12: 11.4 | Q12: 10.796182 | R12: 116000 | S12: 5.2538115 | T12: 8.2882169 | U12: 11.995647
L13: 485.5 | M13: 3.25 | N13: 484 | P13: 11.2 | Q13: 10.596182 | R13: 116100 | S13: 5.2902057 | T13: 8.3305055 | U13: 12.067961
L14: 489 | M14: 2.8 | N14: 489 | P14: 11.1 | Q14: 10.496182 | R14: 116200 | S14: 5.3135176 | T14: 8.4136206 | U14: 12.156324
L15: 490 | M15: 3.22 | N15: 494 | P15: 10.6 | Q15: 9.9961815 | R15: 116300 | S15: 5.323366 | T15: 8.5083388 | U15: 12.171139
L16: 494 | M16: 2.97 | N16: 499 | P16: 11.3 | Q16: 10.696182 | R16: 116400 | S16: 5.3017786 | T16: 8.586549 | U16: 12.224067
L17: 499 | M17: 2.65 | N17: 504 | P17: 11.4 | Q17: 10.796182 | R17: 116500 | S17: 5.3116169 | T17: 8.6438332 | U17: 12.281908
... L22: 524 | M22: 4.365 | N22: 529 | P22: 6 | Q22: 5.3961815 | R22: 117000 | S22: 5.5323664 | T22: 9.0225314 | U22: 12.449403
L23: 544 | M23: 4.375 | R23: 117100 | S23: 5.5860293 | T23: 9.0866088 | U23: 12.461017
R24: 117200 | S24: 5.5735613 | T24: 9.1547622 | U24: 12.461276
R25: 117300 | S25: 5.5861122 | T25: 9.2413322 | U25: 12.438111
R26: 117400 | S26: 5.6118964 | T26: 9.2908588 | U26: 12.452829
R27: 117500 | S27: 5.6498306 | T27: 9.3742843 | U27: 12.4756
R28: 117600 | S28: 5.6593114 | T28: 9.4205312 | U28: 12.485336
R29: 117700 | S29: 5.708967 | T29: 9.4742143 | U29: 12.531608
R30: 117800 | S30: 5.7069915 | T30: 9.5357727 | U30: 12.56392
R31: 117900 | S31: 5.7643482 | T31: 9.580425 | U31: 12.556571
R32: 118000 | S32: 5.805927 | T32: 9.6207058 | U32: 12.595848
R33: 118100 | S33: 5.8714715 | T33: 9.6821799 | U33: 12.61555
R34: 118200 | S34: 5.9227073 | T34: 9.736218 | U34: 12.657767
R35: 118300 | S35: 5.9352485 | T35: 9.7991203 | U35: 12.727962
... R152: 130000 | S152: 4.4571505 | T152: 7.9920808 | U152: 12.488959

Sheet M23414-9
A1: ID | B1: Longitude | C1: Latitude | D1: Proxy | E1: Tie Point Depth (cm) | F1: Tie Point Age (yr) | G1: Tie Point Uncertainty (yr) | H1: Hadley Bias Correction | I1: Hadley uncertainty | J1: TF Uncertainty | K1: SS Uncertainty | L1: Benthic d18O Depth (cm) | M1: Benthic d18O (per mil) | N1: Depth (cm) | O1: Proxy Value | P1: SST (ºC) | Q1: Biascorr | R1: Age (yr) | S1: SST -2sd | T1: SST mean | U1: SST +2sd
A2: M23414-9 | B2: -20.29 | C2: 53.53 | D2: Foram | E2: 329 | F2: 109486 | G2: 1580 | H2: ='HadSST & SynTrACE Bias Estimate'!D4 -> 0.56952399 | I2: ='HadSST & SynTrACE Bias Estimate'!E4 -> 0.14605607 | J2: 1.06 | K2: =SQRT(J2^2+I2^2) -> 1.0700151 | L2: 317.5 | M2: 3.51 | N2: 304 | P2: 9.35 | Q2: 8.780476 | R2: 115000 | S2: 7.454794 | T2: 9.5466396 | U2: 11.572633
E3: 340 | F3: 111224 | G3: 1600 | L3: 322.5 | M3: 3.68 | N3: 309 | P3: 9.8 | Q3: 9.230476 | R3: 115100 | S3: 7.502941 | T3: 9.5706311 | U3: 11.611726
E4: 402 | F4: 127212 | G4: 1427 | L4: 325 | M4: 4.06 | N4: 314 | P4: 8.9 | Q4: 8.330476 | R4: 115200 | S4: 7.5130983 | T4: 9.6056577 | U4: 11.606522
E5: 460 | F5: 136383 | G5: 1304 | L5: 327.5 | M5: 2.6 | N5: 319 | P5: 7.9 | Q5: 7.330476 | R5: 115300 | S5: 7.5279613 | T5: 9.6238662 | U5: 11.625177
E6: 480 | F6: 139396 | G6: 1333 | L6: 330 | M6: 3.88 | N6: 324 | P6: 8.7 | Q6: 8.130476 | R6: 115400 | S6: 7.5760846 | T6: 9.644352 | U6: 11.661535
L7: 332.5 | M7: 4.01 | N7: 329 | P7: 10.3 | Q7: 9.730476 | R7: 115500 | S7: 7.6025168 | T7: 9.6582542 | U7: 11.652459
L8: 335 | M8: 4.12 | N8: 334 | P8: 9 | Q8: 8.430476 | R8: 115600 | S8: 7.5966826 | T8: 9.6821241 | U8: 11.691329
L9: 337.5 | M9: 4.12 | N9: 339 | P9: 10.35 | Q9: 9.780476 | R9: 115700 | S9: 7.6155448 | T9: 9.712859 | U9: 11.707058
L10: 340 | M10: 4.28 | N10: 344 | P10: 8.9 | Q10: 8.330476 | R10: 115800 | S10: 7.6081619 | T10: 9.7609698 | U10: 11.723553
L11: 342.5 | M11: 4.06 | N11: 349 | P11: 9.7 | Q11: 9.130476 | R11: 115900 | S11: 7.6436001 | T11: 9.7686681 | U11: 11.724324
L12: 345 | M12: 4.22 | N12: 354 | P12: 10.85 | Q12: 10.280476 | R12: 116000 | S12: 7.6316662 | T12: 9.7738982 | U12: 11.738873
L13: 347.5 | M13: 4.05 | N13: 364 | P13: 9.8 | Q13: 9.230476 | R13: 116100 | S13: 7.665006 | T13: 9.7944337 | U13: 11.789511
L14: 350 | M14: 4.08 | N14: 374 | P14: 10.55 | Q14: 9.980476 | R14: 116200 | S14: 7.7218868 | T14: 9.8010809 | U14: 11.803165
L15: 352.5 | M15: 3.91 | N15: 379 | P15: 11.3 | Q15: 10.730476 | R15: 116300 | S15: 7.7089716 | T15: 9.7958885 | U15: 11.815388
L16: 355 | M16: 4.12 | N16: 389 | P16: 11.85 | Q16: 11.280476 | R16: 116400 | S16: 7.708627 | T16: 9.7889691 | U16: 11.869251
L17: 357.5 | M17: 3.99 | N17: 394 | P17: 12.2 | Q17: 11.630476 | R17: 116500 | S17: 7.6900862 | T17: 9.8095244 | U17: 11.889261
L18: 360 | M18: 4.22 | N18: 399 | P18: 13.6 | Q18: 13.030476 | R18: 116600 | S18: 7.7337877 | T18: 9.8133986 | U18: 11.881786
... L43: 422.5 | M43: 3.46 | N43: 524 | P43: 2.15 | Q43: 1.580476 | R43: 119100 | S43: 8.0635498 | T43: 10.122874 | U43: 12.558243
L44: 425 | M44: 3.31 | R44: 119200 | S44: 8.0805483 | T44: 10.149217 | U44: 12.582781
L45: 427.5 | M45: 3.68 | R45: 119300 | S45: 8.1001648 | T45: 10.184229 | U45: 12.588081
L46: 430 | M46: 3.86 | R46: 119400 | S46: 8.1246832 | T46: 10.211562 | U46: 12.617861
L47: 432.5 | M47: 3.83 | R47: 119500 | S47: 8.1249053 | T47: 10.245698 | U47: 12.629965
L48: 435 | M48: 3.78 | R48: 119600 | S48: 8.1427634 | T48: 10.277395 | U48: 12.671478
L49: 437.5 | M49: 4.09 | R49: 119700 | S49: 8.1675233 | T49: 10.298717 | U49: 12.698284
L50: 440 | M50: 3.84 | R50: 119800 | S50: 8.1959508 | T50: 10.326056 | U50: 12.747633
L51: 442.5 | M51: 4.76 | R51: 119900 | S51: 8.2083767 | T51: 10.352938 | U51: 12.743855
L52: 445 | M52: 4.4 | R52: 120000 | S52: 8.2705798 | T52: 10.378333 | U52: 12.793497
L53: 447.5 | M53: 4.38 | R53: 120100 | S53: 8.2653903 | T53: 10.413154 | U53: 12.813093
L54: 450 | M54: 5.2 | R54: 120200 | S54: 8.2928348 | T54: 10.456793 | U54: 12.815376
L55: 452.5 | M55: 4.85 | R55: 120300 | S55: 8.3180749 | T55: 10.484528 | U55: 12.851918
... L65: 500 | M65: 5.05 | R65: 121300 | S65: 8.3905533 | T65: 10.819985 | U65: 13.173058
R66: 121400 | S66: 8.4032368 | T66: 10.846388 | U66: 13.200291
R67: 121500 | S67: 8.4058952 | T67: 10.867813 | U67: 13.195691
R68: 121600 | S68: 8.4662423 | T68: 10.902019 | U68: 13.259374
R69: 121700 | S69: 8.4992037 | T69: 10.932798 | U69: 13.263612
R70: 121800 | S70: 8.5388164 | T70: 10.972059 | U70: 13.310616
R71: 121900 | S71: 8.5663492 | T71: 10.993279 | U71: 13.324478
R72: 122000 | S72: 8.6247403 | T72: 11.02143 | U72: 13.341522
R73: 122100 | S73: 8.646397 | T73: 11.057029 | U73: 13.389178
...

Sheet NEAP18k
A1: ID | B1: Longitude | C1: Latitude | D1: Proxy | E1: Tie Point Depth (cm) | F1: Tie Point Age (yr) | G1: Tie Point Uncertainty (yr) | H1: Hadley Bias Correction | I1: Hadley uncertainty | J1: TF Uncertainty | K1: SS Uncertainty | L1: Benthic d18O Depth (cm) | M1: Benthic d18O (per mil) | N1: Depth (cm) | O1: Proxy Value | P1: SST (ºC) | Q1: Biascorr | R1: Age (yr) | S1: SST -2sd | T1: SST mean | U1: SST +2sd
A2: NEAP18k | B2: -30.35 | C2: 52.76 | D2: Foram | E2: 432 | F2: 105470 | G2: 1228 | L2: 280 | M2: 3.9811 | N2: 540 | P2: 8.9 | R2: 115000 | S2: 6.0648 | T2: 9.4954435 | U2: 13.419283
E3: 536 | F3: 111246 | G3: 1600 | L3: 288 | M3: 3.9172 | N3: 548 | P3: 12.1 | R3: 115100 | S3: 6.1446742 | T3: 9.501184 | U3: 13.510671
E4: 594 | F4: 118720 | G4: 1520 | L4: 292 | M4: 3.7632 | N4: 552 | P4: 8.4 | R4: 115200 | S4: 6.1250958 | T4: 9.5255294 | U4: 13.519566
E5: 672 | F5: 127212 | G5: 1427 | L5: 296 | M5: 3.8496 | N5: 556 | P5: 7.4 | R5: 115300 | S5: 6.2980023 | T5: 9.6490876 | U5: 13.621996
L6: 300 | M6: 3.66 | N6: 560 | P6: 8.2 | R6: 115400 | S6: 6.3655825 | T6: 9.7274414 | U6: 13.680765
L7: 302 | M7: 3.8479 | N7: 564 | P7: 9.3 | R7: 115500 | S7: 6.2792541 | T7: 9.8164657 | U7: 13.765202
L8: 304 | M8: 3.73 | N8: 568 | P8: 8.7 | R8: 115600 | S8: 6.27848 | T8: 9.8934297 | U8: 13.73921
L9: 306 | M9: 3.6365 | N9: 572 | P9: 10.6 | R9: 115700 | S9: 6.3194591 | T9: 9.958089 | U9: 13.810061
L10: 308 | M10: 3.66 | N10: 576 | P10: 10.6 | R10: 115800 | S10: 6.4373933 | T10: 9.9970404 | U10: 13.868712
L11: 310 | M11: 3.9953 | N11: 580 | P11: 10.9 | R11: 115900 | S11: 6.4916769 | T11: 10.083314 | U11: 13.944631
L12: 312 | M12: 4.04245 | N12: 584 | P12: 12.1 | R12: 116000 | S12: 6.590263 | T12: 10.233569 | U12: 14.035333
L13: 314 | M13: 4.0339 | N13: 588 | P13: 11.6 | R13: 116100 | S13: 6.5274824 | T13: 10.312179 | U13: 14.063622
L14: 316 | M14: 4.2051 | N14: 592 | P14: 11.7 | R14: 116200 | S14: 6.6832302 | T14: 10.407126 | U14: 14.280321
L15: 318 | M15: 4.2627 | N15: 596 | P15: 13.8 | R15: 116300 | S15: 6.69121 | T15: 10.462864 | U15: 14.332539
L16: 320 | M16: 4.2011 | N16: 600 | P16: 15 | R16: 116400 | S16: 6.8789504 | T16: 10.549057 | U16: 14.508193
L17: 322 | M17: 4.0613 | N17: 604 | P17: 12.1 | R17: 116500 | S17: 6.8566458 | T17: 10.643095 | U17: 14.618139
... L38: 366 | M38: 3.5011 | N38: 674 | P38: 12.8 | R38: 118600 | S38: 8.8982027 | T38: 12.308607 | U38: 15.949126
L39: 368 | M39: 3.51 | R39: 118700 | S39: 9.1292515 | T39: 12.409875 | U39: 16.005799
L40: 370 | M40: 3.6298 | R40: 118800 | S40: 9.0544226 | T40: 12.517529 | U40: 16.017029
L41: 374 | M41: 3.4584 | R41: 118900 | S41: 9.3444719 | T41: 12.602898 | U41: 16.05823
L42: 378 | M42: 3.4371 | R42: 119000 | S42: 9.3160106 | T42: 12.680744 | U42: 16.070629
L43: 380 | M43: 3.3 | R43: 119100 | S43: 9.4425599 | T43: 12.672622 | U43: 16.041948
L44: 382 | M44: 3.5858 | R44: 119200 | S44: 9.5016586 | T44: 12.675133 | U44: 16.180893
L45: 384 | M45: 3.6033 | R45: 119300 | S45: 9.548851 | T45: 12.708551 | U45: 16.245328
L46: 386 | M46: 3.3643 | R46: 119400 | S46: 9.4700413 | T46: 12.762267 | U46: 16.174402
L47: 388 | M47: 3.32 | R47: 119500 | S47: 9.4537909 | T47: 12.830998 | U47: 16.19318
L48: 390 | M48: 3.5531 | R48: 119600 | S48: 9.4552982 | T48: 12.8303 | U48: 16.067028
L49: 392 | M49: 3.2994 | R49: 119700 | S49: 9.4933575 | T49: 12.930496 | U49: 16.104456
L50: 394 | M50: 3.2616 | R50: 119800 | S50: 9.6359388 | T50: 12.929735 | U50: 16.056606
... L152: 594 | M152: 2.9177 | R152: 130000 | S152: 12.07488 | T152: 16.16759 | U152: 19.351352
L153: 595 | M153: 2.8127
L154: 596 | M154: 2.9671
L155: 597 | M155: 2.9042
L156: 598 | M156: 2.73
L157: 599 | M157: 2.74115
L158: 600 | M158: 2.8302333
L159: 601 | M159: 2.8784
L160: 602 | M160: 2.5523
L161: 603 | M161: 2.7708
...

Sheet V23-82
A1: ID | B1: Longitude | C1: Latitude | D1: Proxy | E1: Tie Point Depth (cm) | F1: Tie Point Age (yr) | G1: Tie Point Uncertainty (yr) | H1: Hadley Bias Correction | I1: Hadley uncertainty | J1: TF Uncertainty | K1: SS Uncertainty | L1: Benthic d18O Depth (cm) | M1: Benthic d18O (per mil) | N1: Depth (cm) | O1: Proxy Value | P1: SST (ºC) | Q1: Biascorr | R1: Age (yr) | S1: SST -2sd | T1: SST mean | U1: SST +2sd
A2: V23-82 | B2: -21.93 | C2: 52.58 | D2: Foram | E2: 696 | F2: 111246 | G2: 1600 | H2: ='HadSST & SynTrACE Bias Estimate'!D5 -> 0.55631757 | I2: ='HadSST & SynTrACE Bias Estimate'!E5 -> 0.17057271 | J2: 1.7 | K2: =SQRT(J2^2+I2^2) -> 1.7085359 | L2: 683 | M2: 3.76 | N2: 680 | P2: 6.75 | Q2: 6.1936824 | R2: 115000 | S2: 7.0138489 | T2: 10.171721 | U2: 13.189216
E3: 740 | F3: 118701 | G3: 1520 | L3: 696 | M3: 3.76 | N3: 685 | P3: 5.75 | Q3: 5.1936824 | R3: 115100 | S3: 7.1546311 | T3: 10.15953 | U3: 13.221598
E4: 794 | F4: 127212 | G4: 1427 | L4: 700 | M4: 3.72 | N4: 690 | P4: 7.35 | Q4: 6.7936824 | R4: 115200 | S4: 7.3113261 | T4: 10.219226 | U4: 13.276608
E5: 812 | F5: 132776 | G5: 1351 | L5: 704 | M5: 3.66 | N5: 695 | P5: 8.8 | Q5: 8.2436824 | R5: 115300 | S5: 7.2858485 | T5: 10.25226 | U5: 13.328047
E6: 840 | F6: 136405 | G6: 1304 | L6: 709 | M6: 3.45 | N6: 700 | P6: 10.75 | Q6: 10.193682 | R6: 115400 | S6: 7.2757182 | T6: 10.276946 | U6: 13.444722
L7: 714 | M7: 3.39 | N7: 705 | P7: 10.6 | Q7: 10.043682 | R7: 115500 | S7: 7.3367343 | T7: 10.294181 | U7: 13.377723
L8: 719 | M8: 3.35 | N8: 710 | P8: 9.55 | Q8: 8.9936824 | R8: 115600 | S8: 7.3737031 | T8: 10.341949 | U8: 13.49056
L9: 724 | M9: 3.57 | N9: 715 | P9: 9.45 | Q9: 8.8936824 | R9: 115700 | S9: 7.3449765 | T9: 10.370473 | U9: 13.476329
L10: 729 | M10: 3.0266667 | N10: 720 | P10: 11.3 | Q10: 10.743682 | R10: 115800 | S10: 7.3101638 | T10: 10.400015 | U10: 13.616739
L11: 734 | M11: 3.31 | N11: 725 | P11: 10.45 | Q11: 9.8936824 | R11: 115900 | S11: 7.3453529 | T11: 10.458222 | U11: 13.577679
L12: 740 | M12: 3.13 | N12: 730 | P12: 11.3 | Q12: 10.743682 | R12: 116000 | S12: 7.3695892 | T12: 10.491869 | U12: 13.58542
L13: 741 | M13: 2.87 | N13: 735 | P13: 11.7 | Q13: 11.143682 | R13: 116100 | S13: 7.3694555 | T13: 10.479259 | U13: 13.506044
L14: 754 | M14: 2.64 | N14: 740 | P14: 11.95 | Q14: 11.393682 | R14: 116200 | S14: 7.3762642 | T14: 10.519264 | U14: 13.544267
L15: 764.5 | M15: 2.73 | N15: 745 | P15: 11.15 | Q15: 10.593682 | R15: 116300 | S15: 7.4412093 | T15: 10.573897 | U15: 13.569406
L16: 774 | M16: 2.77 | N16: 750 | P16: 12.8 | Q16: 12.243682 | R16: 116400 | S16: 7.4427481 | T16: 10.628319 | U16: 13.591972
L17: 794.5 | M17: 2.67 | N17: 755 | P17: 11.7 | Q17: 11.143682 | R17: 116500 | S17: 7.4076386 | T17: 10.652304 | U17: 13.735588
L18: 800 | M18: 2.84 | N18: 760 | P18: 12 | Q18: 11.443682 | R18: 116600 | S18: 7.4520512 | T18: 10.675688 | U18: 13.766252
... L21: 849.5 | M21: 4.15 | N21: 773 | P21: 11.45 | Q21: 10.893682 | R21: 116900 | S21: 7.4961049 | T21: 10.755991 | U21: 13.776001
N22: 775 | P22: 12.85 | Q22: 12.293682 | R22: 117000 | S22: 7.569344 | T22: 10.810799 | U22: 13.758387
N23: 777 | P23: 11.25 | Q23: 10.693682 | R23: 117100 | S23: 7.6456295 | T23: 10.849047 | U23: 13.743243
N24: 780 | P24: 10.9 | Q24: 10.343682 | R24: 117200 | S24: 7.6265292 | T24: 10.865138 | U24: 13.801732
N25: 783 | P25: 11.15 | Q25: 10.593682 | R25: 117300 | S25: 7.7420446 | T25: 10.903238 | U25: 13.821084
N26: 785 | P26: 12.15 | Q26: 11.593682 | R26: 117400 | S26: 7.8985153 | T26: 10.927769 | U26: 13.913514
N27: 787 | P27: 11.7 | Q27: 11.143682 | R27: 117500 | S27: 7.8998286 | T27: 10.979999 | U27: 13.926693
N28: 790 | P28: 10.6 | Q28: 10.043682 | R28: 117600 | S28: 8.0405363 | T28: 11.029991 | U28: 13.982452
N29: 793 | P29: 10.95 | Q29: 10.393682 | R29: 117700 | S29: 8.0062664 | T29: 11.029766 | U29: 14.005203
N30: 795 | P30: 9 | Q30: 8.4436824 | R30: 117800 | S30: 8.1588211 | T30: 11.067567 | U30: 14.048958
N31: 797 | P31: 6.45 | Q31: 5.8936824 | R31: 117900 | S31: 8.1394587 | T31: 11.094871 | U31: 14.145567
N32: 800 | P32: 4.15 | Q32: 3.5936824 | R32: 118000 | S32: 8.1565473 | T32: 11.10667 | U32: 14.038212
N33: 803 | P33: 3.75 | Q33: 3.1936824 | R33: 118100 | S33: 8.1436322 | T33: 11.124662 | U33: 13.984164
... N48: 847 | P48: 3.5 | Q48: 2.9436824 | R48: 119600 | S48: 8.4142214 | T48: 11.456608 | U48: 14.359521
R49: 119700 | S49: 8.468478 | T49: 11.472943 | U49: 14.44499
R50: 119800 | S50: 8.5079607 | T50: 11.496558 | U50: 14.397335
R51: 119900 | S51: 8.4304535 | T51: 11.51741 | U51: 14.450653
R52: 120000 | S52: 8.5088292 | T52: 11.53788 | U52: 14.492201
R53: 120100 | S53: 8.5458041 | T53: 11.582343 | U53: 14.450662
R54: 120200 | S54: 8.5912679 | T54: 11.622525 | U54: 14.345492
R55: 120300 | S55: 8.6605549 | T55: 11.590386 | U55: 14.374587
R56: 120400 | S56: 8.7339013 | T56: 11.58713 | U56: 14.440538
...

Sheet K708-1
A1: ID | B1: Longitude | C1: Latitude | D1: Proxy | E1: Tie Point Depth (cm) | F1: Tie Point Age (yr) | G1: Tie Point Uncertainty (yr) | H1: Hadley Bias Correction | I1: Hadley uncertainty | J1: TF Uncertainty | K1: SS Uncertainty | L1: Benthic d18O Depth (cm) | M1: Benthic d18O (per mil) | N1: Depth (cm) | O1: Proxy Value | P1: SST (ºC) | Q1: Biascorr | R1: Age (yr) | S1: SST -2sd | T1: SST mean | U1: SST +2sd
A2: K708-1 | B2: -23.74 | C2: 50 | D2: Foram | E2: 760 | F2: 112939 | G2: 1583 | H2: ='HadSST & SynTrACE Bias Estimate'!D6 -> 0.62224519 | I2: ='HadSST & SynTrACE Bias Estimate'!E6 -> 0.23647614 | J2: 1.4 | K2: =SQRT(I2^2+J2^2) -> 1.4198313 | L2: 730 | M2: 3.79 | N2: 740 | P2: 13 | Q2: 12.377755 | R2: 115000 | S2: 6.5003733 | T2: 12.032709 | U2: 16.152561
E3: 795 | F3: 122438 | G3: 1479 | L3: 745 | M3: 4.01 | N3: 760 | P3: 7.65 | Q3: 7.0277548 | R3: 115100 | S3: 6.6197818 | T3: 12.194419 | U3: 16.196062
E4: 850 | F4: 127212 | G4: 1427 | L4: 760 | M4: 4.08 | N4: 770 | P4: 14.25 | Q4: 13.627755 | R4: 115200 | S4: 6.5761401 | T4: 12.385318 | U4: 16.231012
E5: 870 | F5: 136361 | G5: 1304 | L5: 765 | M5: 3.61 | N5: 780 | P5: 14.45 | Q5: 13.827755 | R5: 115300 | S5: 6.7270268 | T5: 12.535345 | U5: 16.290819
L6: 775 | M6: 3.64 | N6: 785 | P6: 15.4 | Q6: 14.777755 | R6: 115400 | S6: 6.799725 | T6: 12.699968 | U6: 16.441334
L7: 790 | M7: 3.385 | N7: 790 | P7: 17.25 | Q7: 16.627755 | R7: 115500 | S7: 6.929239 | T7: 12.82145 | U7: 16.549719
L8: 795 | M8: 2.47 | N8: 795 | P8: 17.25 | Q8: 16.627755 | R8: 115600 | S8: 7.1890526 | T8: 12.921256 | U8: 16.618102
L9: 800 | M9: 3.36 | N9: 800 | P9: 15.6 | Q9: 14.977755 | R9: 115700 | S9: 7.2464921 | T9: 13.0298 | U9: 16.656812
L10: 815 | M10: 2.97 | N10: 805 | P10: 15.3 | Q10: 14.677755 | R10: 115800 | S10: 7.3160603 | T10: 13.146404 | U10: 16.691933
L11: 820 | M11: 2.85 | N11: 810 | P11: 14.95 | Q11: 14.327755 | R11: 115900 | S11: 7.4988959 | T11: 13.287737 | U11: 16.721203
L12: 825 | M12: 2.99 | N12: 815 | P12: 15.5 | Q12: 14.877755 | R12: 116000 | S12: 7.5693268 | T12: 13.388419 | U12: 16.817876
L13: 830 | M13: 3.07 | N13: 820 | P13: 15.1 | Q13: 14.477755 | R13: 116100 | S13: 7.7123022 | T13: 13.47756 | U13: 16.903695
L14: 845 | M14: 3.35 | N14: 825 | P14: 16.5 | Q14: 15.877755 | R14: 116200 | S14: 7.8430664 | T14: 13.550138 | U14: 17.087014
L15: 848 | M15: 2.83 | N15: 830 | P15: 16.6 | Q15: 15.977755 | R15: 116300 | S15: 7.9605311 | T15: 13.593394 | U15: 17.233474
L16: 850 | M16: 2.78 | N16: 835 | P16: 14.15 | Q16: 13.527755 | R16: 116400 | S16: 8.1052104 | T16: 13.651724 | U16: 17.295727
L17: 870 | M17: 4.35 | N17: 840 | P17: 14.65 | Q17: 14.027755 | R17: 116500 | S17: 8.2233086 | T17: 13.707914 | U17: 17.374501
L18: 875 | M18: 4.3 | N18: 845 | P18: 14.35 | Q18: 13.727755 | R18: 116600 | S18: 8.3161383 | T18: 13.758799 | U18: 17.415618
N19: 848 | P19: 13.9 | Q19: 13.277755 | R19: 116700 | S19: 8.4308206 | T19: 13.825552 | U19: 17.456367
N20: 850 | P20: 14.45 | Q20: 13.827755 | R20: 116800 | S20: 8.8012082 | T20: 13.869395 | U20: 17.482232
N21: 853 | P21: 11.85 | Q21: 11.227755 | R21: 116900 | S21: 9.1311473 | T21: 13.950511 | U21: 17.57394
N22: 855 | P22: 6.9 | Q22: 6.2777548 | R22: 117000 | S22: 9.3946452 | T22: 14.019171 | U22: 17.668881
N23: 858 | P23: 5.75 | Q23: 5.1277548 | R23: 117100 | S23: 9.5750768 | T23: 14.064434 | U23: 17.684452
N24: 860 | P24: 6.4 | Q24: 5.7777548 | R24: 117200 | S24: 9.7366258 | T24: 14.103191 | U24: 17.753591
N25: 863 | P25: 7 | Q25: 6.3777548 | R25: 117300 | S25: 9.8954783 | T25: 14.137765 | U25: 17.746206
N26: 865 | P26: 2.95 | Q26: 2.3277548 | R26: 117400 | S26: 10.092563 | T26: 14.203759 | U26: 17.790147
N27: 870 | P27: 3.3 | Q27: 2.6777548 | R27: 117500 | S27: 10.267011 | T27: 14.253478 | U27: 17.87979
N28: 875 | P28: 3.9 | Q28: 3.2777548 | R28: 117600 | S28: 10.414873 | T28: 14.296726 | U28: 17.916067
N29: 880 | P29: 5.4 | Q29: 4.7777548 | R29: 117700 | S29: 10.505239 | T29: 14.356069 | U29: 17.924466
R30: 117800 | S30: 10.604353 | T30: 14.394321 | U30: 17.991357
R31: 117900 | S31: 10.684447 | T31: 14.455587 | U31: 17.988814
R32: 118000 | S32: 10.779079 | T32: 14.498493 | U32: 18.057018
R33: 118100 | S33: 10.944722 | T33: 14.575014 | U33: 18.097862
R34: 118200 | S34: 11.08267 | T34: 14.64516 | U34: 18.138196
R35: 118300 | S35: 11.133198 | T35: 14.710491 | U35: 18.250289
R36: 118400 | S36: 11.260764 | T36: 14.775976 | U36: 18.272437
R37: 118500 | S37: 11.274227 | T37: 14.845176 | U37: 18.280191
R38: 118600 | S38: 11.370968 | T38: 14.92621 | U38: 18.318876
R39: 118700 | S39: 11.419454 | T39: 14.996798 | U39: 18.390745
R40: 118800 | S40: 11.483229 | T40: 15.045496 | U40: 18.36621
...

Sheet MD04-2845
A1: ID | B1: Longitude | C1: Latitude | D1: Proxy | E1: Tie Point Depth (cm) | F1: Tie Point Age (yr) | G1: Tie Point Uncertainty (yr) | H1: Hadley Bias Correction | I1: Hadley uncertainty | J1: TF Uncertainty | K1: SS Uncertainty | L1: Benthic d18O Depth (cm) | M1: Benthic d18O (per mil) | N1: Depth (cm) | O1: Proxy Value | P1: SST (ºC) | Q1: Biascorr | R1: Age (yr) | S1: SST -2sd | T1: SST mean | U1: SST +2sd
A2: MD04-2845 | B2: -5.22 | C2: 45.35 | D2: Foram | E2: 2015 | F2: 105355 | G2: 1234 | L2: 2000 | M2: 3.3658441 | N2: 2000 | P2: 19.9 | R2: 115000 | S2: 14.481544 | T2: 18.167181 | U2: 21.311719
E3: 2045 | F3: 111202 | G3: 1600 | L3: 2005 | M3: 3.3223164 | N3: 2010 | P3: 12.7 | R3: 115100 | S3: 14.682382 | T3: 18.376356 | U3: 21.364418
E4: 2071 | F4: 118704 | G4: 1520 | L4: 2010 | M4: 3.4536404 | N4: 2020 | P4: 17.1 | R4: 115200 | S4: 14.638927 | T4: 18.556546 | U4: 21.469375
E5: 2120 | F5: 127210 | G5: 1427 | L5: 2015 | M5: 3.5554825 | N5: 2030 | P5: 16.2 | R5: 115300 | S5: 14.682415 | T5: 18.690017 | U5: 21.528189
E6: 2162 | F6: 136383 | G6: 1304 | L6: 2020 | M6: 3.414989 | N6: 2035 | P6: 10.6 | R6: 115400 | S6: 14.737174 | T6: 18.835735 | U6: 21.57208
L7: 2022 | M7: 3.3670903 | N7: 2040 | P7: 6.3 | R7: 115500 | S7: 14.882453 | T7: 18.938162 | U7: 21.615811
L8: 2025 | M8: 3.3910599 | N8: 2045 | P8: 14.6 | R8: 115600 | S8: 15.030762 | T8: 19.039092 | U8: 21.640601
L9: 2030 | M9: 3.2801074 | N9: 2050 | P9: 18.4 | R9: 115700 | S9: 14.995683 | T9: 19.102877 | U9: 21.705505
L10: 2032 | M10: 3.3236252 | N10: 2055 | P10: 15.1 | R10: 115800 | S10: 15.087983 | T10: 19.189491 | U10: 21.74411
L11: 2035 | M11: 3.6301532 | N11: 2060 | P11: 19.4 | R11: 115900 | S11: 15.153251 | T11: 19.270221 | U11: 21.7143
L12: 2037 | M12: 3.5630468 | N12: 2065 | P12: 20.7 | R12: 116000 | S12: 15.193675 | T12: 19.357513 | U12: 21.740944
L13: 2040 | M13: 3.6024309 | N13: 2070 | P13: 18.6 | R13: 116100 | S13: 15.248568 | T13: 19.415546 | U13: 21.747944
L14: 2042 | M14: 3.5397162 | N14: 2075 | P14: 20.5 | R14: 116200 | S14: 15.291659 | T14: 19.48934 | U14: 21.812334
L15: 2045 | M15: 3.5606857 | N15: 2080 | P15: 20.8 | R15: 116300 | S15: 15.37867 | T15: 19.484761 | U15: 21.757614
L16: 2047 | M16: 3.4009847 | N16: 2082 | P16: 21.5 | R16: 116400 | S16: 15.398726 | T16: 19.521256 | U16: 21.767655
L17: 2050 | M17: 3.498149 | N17: 2085 | P17: 22.1 | R17: 116500 | S17: 15.555562 | T17: 19.538471 | U17: 21.84604
L18: 2052 | M18: 3.402004 | N18: 2087 | P18: 20.8 | R18: 116600 | S18: 15.618327 | T18: 19.562585 | U18: 21.838804
... L49: 2132 | M49: 4.1343629 | N49: 2165 | P49: 13.6 | R49: 119700 | S49: 17.638118 | T49: 20.300977 | U49: 22.827396
L50: 2135 | M50: 4.6814994 | R50: 119800 | S50: 17.621705 | T50: 20.292287 | U50: 22.883917
L51: 2137 | M51: 2.869881 | R51: 119900 | S51: 17.654215 | T51: 20.292463 | U51: 22.899727
L52: 2140 | M52: 3.2697617 | R52: 120000 | S52: 17.643628 | T52: 20.294496 | U52: 22.830007
L53: 2147 | M53: 3.4917291 | R53: 120100 | S53: 17.674755 | T53: 20.266828 | U53: 22.859014
L54: 2150 | M54: 4.3998384 | R54: 120200 | S54: 17.636625 | T54: 20.256027 | U54: 22.891681
L55: 2155 | M55: 3.5894573 | R55: 120300 | S55: 17.621796 | T55: 20.277917 | U55: 22.973279
L56: 2157 | M56: 4.3564511 | R56: 120400 | S56: 17.587285 | T56: 20.306293 | U56: 22.946953
L57: 2160 | M57: 4.3645736 | R57: 120500 | S57: 17.48641 | T57: 20.261993 | U57: 22.863702
L58: 2162 | M58: 4.4822922 | R58: 120600 | S58: 17.427049 | T58: 20.236824 | U58: 22.805297
L59: 2165 | M59: 4.3442634 | R59: 120700 | S59: 17.516101 | T59: 20.210186 | U59: 22.839721
R60: 120800 | S60: 17.422919 | T60: 20.206016 | U60: 22.784425
R61: 120900 | S61: 17.463866 | T61: 20.150604 | U61: 22.815106
R62: 121000 | S62: 17.333246 | T62: 20.148875 | U62: 22.833863
